<?xml version="1.0" encoding="utf-8"?>
<!-- This URDF was automatically created by SolidWorks to URDF Exporter! Originally created by Stephen Brawner (brawner@gmail.com) 
     Commit Version: 1.6.0-4-g7f85cfe  Build Version: 1.6.7995.38578
     For more information, please see http://wiki.ros.org/sw_urdf_exporter -->
<robot
  name="full_tesla_truck_urdf">
  <link
    name="base_link">
    <inertial>
      <origin
        xyz="0.00910777989909624 0 -0.0337255398760613"
        rpy="0 0 0" />
      <mass
        value="1.01774082387667" />
      <inertia
        ixx="0.00123679000195554"
        ixy="4.78648099154926E-20"
        ixz="-3.11720525242503E-05"
        iyy="0.00293732187940151"
        iyz="1.98612471063947E-20"
        izz="0.0036540907711409" />
    </inertial>
    <visual>
      <origin
        xyz="0 0 0"
        rpy="0 0 0" />
      <geometry>
        <mesh
          filename="package://full_tesla_truck_urdf/meshes/base_link.STL" />
      </geometry>
      <material
        name="">
        <color
          rgba="0.792156862745098 0.819607843137255 0.933333333333333 1" />
      </material>
    </visual>
    <collision>
      <origin
        xyz="0 0 0"
        rpy="0 0 0" />
      <geometry>
        <mesh
          filename="package://full_tesla_truck_urdf/meshes/base_link.STL" />
      </geometry>
    </collision>
  </link>
  <link
    name="front_left_link">
    <inertial>
      <origin
        xyz="0 -0.005 0"
        rpy="0 0 0" />
      <mass
        value="0.0066289" />
      <inertia
        ixx="4.3359E-07"
        ixy="-2.7573E-25"
        ixz="5.076E-23"
        iyy="7.6063E-07"
        iyz="4.1359E-24"
        izz="4.3359E-07" />
    </inertial>
    <visual>
      <origin
        xyz="0 0 0"
        rpy="0 0 0" />
      <geometry>
        <mesh
          filename="package://full_tesla_truck_urdf/meshes/front_left_link.STL" />
      </geometry>
      <material
        name="">
        <color
          rgba="0.79216 0.81961 0.93333 1" />
      </material>
    </visual>
    <collision>
      <origin
        xyz="0 0 0"
        rpy="0 0 0" />
      <geometry>
        <mesh
          filename="package://full_tesla_truck_urdf/meshes/front_left_link.STL" />
      </geometry>
    </collision>
  </link>
  <joint
    name="front_left_joint"
    type="continuous">
    <origin
      xyz="0.06153 0.054495 -0.056567"
      rpy="0 0 0" />
    <parent
      link="base_link" />
    <child
      link="front_left_link" />
    <axis
      xyz="0 -1 0" />
    <limit
      lower="0"
      upper="0"
      effort="0"
      velocity="0" />
  </joint>
  <link
    name="back_left_link">
    <inertial>
      <origin
        xyz="3.4694E-18 -0.005 0"
        rpy="0 0 0" />
      <mass
        value="0.0066289" />
      <inertia
        ixx="4.3359E-07"
        ixy="1.1029E-24"
        ixz="2.93E-23"
        iyy="7.6063E-07"
        iyz="-1.7922E-24"
        izz="4.3359E-07" />
    </inertial>
    <visual>
      <origin
        xyz="0 0 0"
        rpy="0 0 0" />
      <geometry>
        <mesh
          filename="package://full_tesla_truck_urdf/meshes/back_left_link.STL" />
      </geometry>
      <material
        name="">
        <color
          rgba="0.79216 0.81961 0.93333 1" />
      </material>
    </visual>
    <collision>
      <origin
        xyz="0 0 0"
        rpy="0 0 0" />
      <geometry>
        <mesh
          filename="package://full_tesla_truck_urdf/meshes/back_left_link.STL" />
      </geometry>
    </collision>
  </link>
  <joint
    name="back_left_joint"
    type="continuous">
    <origin
      xyz="-0.049669 0.054511 -0.056567"
      rpy="0 0 0" />
    <parent
      link="base_link" />
    <child
      link="back_left_link" />
    <axis
      xyz="0 -1 0" />
    <limit
      lower="0"
      upper="0"
      effort="0"
      velocity="0" />
  </joint>
  <link
    name="front_right_link">
    <inertial>
      <origin
        xyz="0 0.005 0"
        rpy="0 0 0" />
      <mass
        value="0.0066289" />
      <inertia
        ixx="4.3359E-07"
        ixy="-2.8345E-24"
        ixz="5.0785E-24"
        iyy="7.6063E-07"
        iyz="-1.8072E-24"
        izz="4.3359E-07" />
    </inertial>
    <visual>
      <origin
        xyz="0 0 0"
        rpy="0 0 0" />
      <geometry>
        <mesh
          filename="package://full_tesla_truck_urdf/meshes/front_right_link.STL" />
      </geometry>
      <material
        name="">
        <color
          rgba="0.79216 0.81961 0.93333 1" />
      </material>
    </visual>
    <collision>
      <origin
        xyz="0 0 0"
        rpy="0 0 0" />
      <geometry>
        <mesh
          filename="package://full_tesla_truck_urdf/meshes/front_right_link.STL" />
      </geometry>
    </collision>
  </link>
  <joint
    name="front_right_joint"
    type="continuous">
    <origin
      xyz="0.06153 -0.054505 -0.056567"
      rpy="0 0 0" />
    <parent
      link="base_link" />
    <child
      link="front_right_link" />
    <axis
      xyz="0 1 0" />
    <limit
      lower="0"
      upper="0"
      effort="0"
      velocity="0" />
  </joint>
  <link
    name="back_right_link">
    <inertial>
      <origin
        xyz="3.4694E-18 0.005 1.3878E-17"
        rpy="0 0 0" />
      <mass
        value="0.0066289" />
      <inertia
        ixx="4.3359E-07"
        ixy="-3.108E-24"
        ixz="-2.4808E-23"
        iyy="7.6063E-07"
        iyz="-1.6326E-24"
        izz="4.3359E-07" />
    </inertial>
    <visual>
      <origin
        xyz="0 0 0"
        rpy="0 0 0" />
      <geometry>
        <mesh
          filename="package://full_tesla_truck_urdf/meshes/back_right_link.STL" />
      </geometry>
      <material
        name="">
        <color
          rgba="0.79216 0.81961 0.93333 1" />
      </material>
    </visual>
    <collision>
      <origin
        xyz="0 0 0"
        rpy="0 0 0" />
      <geometry>
        <mesh
          filename="package://full_tesla_truck_urdf/meshes/back_right_link.STL" />
      </geometry>
    </collision>
  </link>
  <joint
    name="back_right_joint"
    type="continuous">
    <origin
      xyz="-0.049669 -0.054464 -0.056567"
      rpy="0 0 0" />
    <parent
      link="base_link" />
    <child
      link="back_right_link" />
    <axis
      xyz="0 1 0" />
    <limit
      lower="0"
      upper="0"
      effort="0"
      velocity="0" />
  </joint>
</robot>
