<?xml version="1.0" ?>
<robot name="two_wheel_robot" xmlns:xacro="http://ros.org/wiki/xacro">
  <xacro:include filename="$(find robot)/gazebo/two_wheel_robot.gazebo"/>

  <link name="base_link">
    <inertial>
      <mass value="5"/>
      <origin xyz="0 0 0" rpy="0 0 0"/>
      <inertia ixx="0.0791667" ixy="0" ixz="0" iyy="0.0791667" iyz="0" izz="0.15625"/>
    </inertial>
    <collision>
      <origin xyz="-0.04     0.00081  0.02625" rpy="0 0 0"/>
      <geometry>
        <cylinder radius="0.25" length="0.05"/>
      </geometry>
    </collision>
    <visual>
      <origin xyz="-0.04     0.00081  0.02625" rpy="0 0 0"/>
      <geometry>
        <cylinder radius="0.25" length="0.05"/>
      </geometry>
    </visual>
  </link>
  
  
  <joint name="right_joint" type="revolute">
    <parent link="base_link"/>
    <child link="right_link"/>
    <origin xyz="-0.06625  0.26475  0.00125" rpy="1.5708 0     0"/>
    <axis xyz="0 0 1"/>
    <limit lower="-1.79769e+308" upper="1.79769e+308" effort="-1.0" velocity="-1.0"/>
  </joint>
  
  <link name="right_link">
    <inertial>
      <mass value="1"/>
      <origin xyz="0 0 0" rpy="0 0 0"/>
      <inertia ixx="0.145833" ixy="0" ixz="0" iyy="0.145833" iyz="0" izz="0.125"/>
    </inertial>
    <collision>
      <origin xyz="0 0 0" rpy="0 0 0"/>
      <geometry>
        <cylinder radius="0.06" length="0.02"/>
      </geometry>
    </collision>
    <visual>
      <origin xyz="0 0 0" rpy="0 0 0"/>
      <geometry>
        <cylinder radius="0.06" length="0.02"/>
      </geometry>
    </visual>
  </link>
  
  
  <joint name="left_joint" type="revolute">
    <parent link="base_link"/>
    <child link="left_link"/>
    <origin xyz="-0.06625 -0.26338  0.00125" rpy="1.5708 0     0"/>
    <axis xyz="0 0 1"/>
    <limit lower="-1.79769e+308" upper="1.79769e+308" effort="-1.0" velocity="-1.0"/>
  </joint>
  
  <link name="left_link">
    <inertial>
      <mass value="1"/>
      <origin xyz="0 0 0" rpy="0 0 0"/>
      <inertia ixx="0.145833" ixy="0" ixz="0" iyy="0.145833" iyz="0" izz="0.125"/>
    </inertial>
    <collision>
      <origin xyz="0 0 0" rpy="0 0 0"/>
      <geometry>
        <cylinder radius="0.06" length="0.02"/>
      </geometry>
    </collision>
    <visual>
      <origin xyz="0 0 0" rpy="0 0 0"/>
      <geometry>
        <cylinder radius="0.06" length="0.02"/>
      </geometry>
    </visual>
  </link>
  
  
  <joint name="caster_joint" type="fixed">
    <parent link="base_link"/>
    <child link="caster_link"/>
    <origin xyz="0.17252 -0.00218 -0.02875" rpy="0 0 0"/>
    <axis xyz="0 0 0"/>
    <limit lower="0" upper="0" effort="0" velocity="0"/>
  </joint>
  
  <link name="caster_link">
    <inertial>
      <mass value="1"/>
      <origin xyz="0 0 0" rpy="0 0 0"/>
      <inertia ixx="0.1" ixy="0" ixz="0" iyy="0.1" iyz="0" izz="0.1"/>
    </inertial>
    <collision>
      <origin xyz="0 0 0" rpy="0 0 0"/>
      <geometry>
        <sphere radius="0.03"/>
      </geometry>
    </collision>
    <visual>
      <origin xyz="0 0 0" rpy="0 0 0"/>
      <geometry>
        <sphere radius="0.03"/>
      </geometry>
    </visual>
  </link>
  
  
  <joint name="lidar_joint" type="fixed">
    <parent link="base_link"/>
    <child link="lidar_link"/>
    <origin xyz="-0.04562  0.00404  0.07809" rpy="0       0      -0.05443"/>
    <axis xyz="0 0 0"/>
    <limit lower="0" upper="0" effort="0" velocity="0"/>
  </joint>
  
  <link name="lidar_link">
    <inertial>
      <mass value="1"/>
      <origin xyz="0 0 0" rpy="0 0 0"/>
      <inertia ixx="0.145833" ixy="0" ixz="0" iyy="0.145833" iyz="0" izz="0.125"/>
    </inertial>
    <collision>
      <origin xyz="0 0 0" rpy="0 0 0"/>
      <geometry>
        <cylinder radius="0.075" length="0.06"/>
      </geometry>
    </collision>
    <visual>
      <origin xyz="0 0 0" rpy="0 0 0"/>
      <geometry>
        <cylinder radius="0.075" length="0.06"/>
      </geometry>
    </visual>
  </link>
  
  
  <joint name="camera_joint" type="fixed">
    <parent link="base_link"/>
    <child link="camera_link"/>
    <origin xyz="-0.29806 -0.00575  0.02453" rpy="0      0      3.14157"/>
    <axis xyz="0 0 0"/>
    <limit lower="0" upper="0" effort="0" velocity="0"/>
  </joint>
  
  <link name="camera_link">
    <inertial>
      <mass value="1"/>
      <origin xyz="0 0 0" rpy="0 0 0"/>
      <inertia ixx="0.166667" ixy="0" ixz="0" iyy="0.166667" iyz="0" izz="0.166667"/>
    </inertial>
    <collision>
      <origin xyz="0 0 0" rpy="0 0 0"/>
      <geometry>
        <box size="0.05 0.05 0.05"/>
      </geometry>
    </collision>
    <visual>
      <origin xyz="0 0 0" rpy="0 0 0"/>
      <geometry>
        <box size="0.05 0.05 0.05"/>
      </geometry>
    </visual>
  </link>
  
  
  <joint name="camera_frame_joint" type="fixed">
    <parent link="camera_link"/>
    <child link="camera_frame_link"/>
    <origin xyz="-0.29806 -0.00575  0.02453" rpy="-1.5708      0      -1.5708"/>
    <axis xyz="0 0 0"/>
    <limit lower="0" upper="0" effort="0" velocity="0"/>
  </joint>
  
  <link name="camera_frame_link" />
 
</robot>
