<?xml version="1.0" encoding="utf-8"?>
<!-- This URDF was automatically created by SolidWorks to URDF Exporter! Originally created by Stephen Brawner (brawner@gmail.com) 
     Commit Version: 1.6.0-4-g7f85cfe  Build Version: 1.6.7995.38578
     For more information, please see http://wiki.ros.org/sw_urdf_exporter -->
<robot
  name="ros_dharmendra_urdf">
  <link
    name="base_link">
    <inertial>
      <origin
        xyz="-0.0063727 3.1468E-09 -0.027165"
        rpy="0 0 0" />
      <mass
        value="0.57979" />
      <inertia
        ixx="0.00036672"
        ixy="-6.0661E-11"
        ixz="-6.4146E-05"
        iyy="0.0018919"
        iyz="-1.5777E-10"
        izz="0.0020754" />
    </inertial>
    <visual>
      <origin
        xyz="0 0 0"
        rpy="0 0 0" />
      <geometry>
        <mesh
          filename="package://ros_dharmendra_urdf/meshes/base_link.STL" />
      </geometry>
      <material
        name="">
        <color
          rgba="0.79216 0.81961 0.93333 1" />
      </material>
    </visual>
    <collision>
      <origin
        xyz="0 0 0"
        rpy="0 0 0" />
      <geometry>
        <mesh
          filename="package://ros_dharmendra_urdf/meshes/base_link.STL" />
      </geometry>
    </collision>
  </link>
  <link
    name="back_left_wheel">
    <inertial>
      <origin
        xyz="0 0 0"
        rpy="0 0 0" />
      <mass
        value="0.0055484" />
      <inertia
        ixx="5.5246E-07"
        ixy="-2.2255E-24"
        ixz="2.9406E-23"
        iyy="1.0532E-06"
        iyz="1.3357E-24"
        izz="5.5246E-07" />
    </inertial>
    <visual>
      <origin
        xyz="0 0 0"
        rpy="0 0 0" />
      <geometry>
        <mesh
          filename="package://ros_dharmendra_urdf/meshes/back_left_wheel.STL" />
      </geometry>
      <material
        name="">
        <color
          rgba="0.79216 0.81961 0.93333 1" />
      </material>
    </visual>
    <collision>
      <origin
        xyz="0 0 0"
        rpy="0 0 0" />
      <geometry>
        <mesh
          filename="package://ros_dharmendra_urdf/meshes/back_left_wheel.STL" />
      </geometry>
    </collision>
  </link>
  <joint
    name="back_left_joint"
    type="continuous">
    <origin
      xyz="0.06211 -0.0438 -0.036"
      rpy="0 0 3.1416" />
    <parent
      link="base_link" />
    <child
      link="back_left_wheel" />
    <axis
      xyz="0 -1 0" />
  </joint>
  <link
    name="back_right_wheel">
    <inertial>
      <origin
        xyz="0 0 0"
        rpy="0 0 0" />
      <mass
        value="0.0055484" />
      <inertia
        ixx="5.5246E-07"
        ixy="-2.2255E-24"
        ixz="2.9406E-23"
        iyy="1.0532E-06"
        iyz="1.3357E-24"
        izz="5.5246E-07" />
    </inertial>
    <visual>
      <origin
        xyz="0 0 0"
        rpy="0 0 0" />
      <geometry>
        <mesh
          filename="package://ros_dharmendra_urdf/meshes/back_right_wheel.STL" />
      </geometry>
      <material
        name="">
        <color
          rgba="0.79216 0.81961 0.93333 1" />
      </material>
    </visual>
    <collision>
      <origin
        xyz="0 0 0"
        rpy="0 0 0" />
      <geometry>
        <mesh
          filename="package://ros_dharmendra_urdf/meshes/back_right_wheel.STL" />
      </geometry>
    </collision>
  </link>
  <joint
    name="back_right_joint"
    type="continuous">
    <origin
      xyz="0.06211 0.0438 -0.036"
      rpy="0 0 3.1416" />
    <parent
      link="base_link" />
    <child
      link="back_right_wheel" />
    <axis
      xyz="0 -1 0" />
  </joint>
  <link
    name="front_right_wheel">
    <inertial>
      <origin
        xyz="0 0 1.3878E-17"
        rpy="0 0 0" />
      <mass
        value="0.0026487" />
      <inertia
        ixx="1.3876E-07"
        ixy="1.6729E-24"
        ixz="9.497E-40"
        iyy="2.4899E-07"
        iyz="1.4027E-40"
        izz="1.3876E-07" />
    </inertial>
    <visual>
      <origin
        xyz="0 0 0"
        rpy="0 0 0" />
      <geometry>
        <mesh
          filename="package://ros_dharmendra_urdf/meshes/front_right_wheel.STL" />
      </geometry>
      <material
        name="">
        <color
          rgba="0.79216 0.81961 0.93333 1" />
      </material>
    </visual>
    <collision>
      <origin
        xyz="0 0 0"
        rpy="0 0 0" />
      <geometry>
        <mesh
          filename="package://ros_dharmendra_urdf/meshes/front_right_wheel.STL" />
      </geometry>
    </collision>
  </link>
  <joint
    name="front_right_joint"
    type="continuous">
    <origin
      xyz="-0.07789 0.0435 -0.041"
      rpy="0 0 0" />
    <parent
      link="base_link" />
    <child
      link="front_right_wheel" />
    <axis
      xyz="0 1 0" />
  </joint>
  <link
    name="front_left_wheel">
    <inertial>
      <origin
        xyz="0 2.7756E-17 1.3878E-17"
        rpy="0 0 0" />
      <mass
        value="0.0026487" />
      <inertia
        ixx="1.3876E-07"
        ixy="1.6729E-24"
        ixz="-9.497E-40"
        iyy="2.4899E-07"
        iyz="-1.4027E-40"
        izz="1.3876E-07" />
    </inertial>
    <visual>
      <origin
        xyz="0 0 0"
        rpy="0 0 0" />
      <geometry>
        <mesh
          filename="package://ros_dharmendra_urdf/meshes/front_left_wheel.STL" />
      </geometry>
      <material
        name="">
        <color
          rgba="0.79216 0.81961 0.93333 1" />
      </material>
    </visual>
    <collision>
      <origin
        xyz="0 0 0"
        rpy="0 0 0" />
      <geometry>
        <mesh
          filename="package://ros_dharmendra_urdf/meshes/front_left_wheel.STL" />
      </geometry>
    </collision>
  </link>
  <joint
    name="front_left_joint"
    type="continuous">
    <origin
      xyz="-0.07789 -0.0435 -0.041"
      rpy="0 0 3.1416" />
    <parent
      link="base_link" />
    <child
      link="front_left_wheel" />
    <axis
      xyz="0 -1 0" />
  </joint>
</robot>