<?xml version="1.0" encoding="utf-8"?>
<!-- This URDF was automatically created by SolidWorks to URDF Exporter! Originally created by Stephen Brawner (brawner@gmail.com) 
     Commit Version: 1.6.0-4-g7f85cfe  Build Version: 1.6.7995.38578
     For more information, please see http://wiki.ros.org/sw_urdf_exporter -->
<robot name="omni_vehicle_urdf" xmlns:xacro="http://ros.org/wiki/xacro">
<xacro:include filename="$(find omni_vehicle_urdf)/gazebo/omni_vehicle_urdf.gazebo"/>

   <!--link name= "base_footprint" /> 
 
  <joint name="base_joint" type="fixed">
    <parent link="base_footprint"/>
    <child link="base_link"/>
    <origin xyz="0 0  0" rpy="0 0 0"/>
  </joint-->
  
  <link name="base_link">
    <inertial>
      <origin
        xyz="0.00068708 0.00011581 0.017546"
        rpy="0 0 0" />
      <mass   value="0.64588" />
      <inertia
        ixx="0.0033271"
        ixy="-1.4375E-07"
        ixz="9.238E-08"
        iyy="0.0033272"
        iyz="-1.2494E-07"
        izz="0.0065629" />
    </inertial>
    <visual>
      <origin
        xyz="0 0 0"
        rpy="0 0 0" />
      <geometry>
        <mesh
          filename="package://omni_vehicle_urdf/meshes/base_link.STL" />
      </geometry>
      <material
        name="">
        <color
          rgba="0.79216 0.81961 0.93333 1" />
      </material>
    </visual>
    <collision>
      <origin
        xyz="0 0 0"
        rpy="0 0 0" />
      <geometry>
        <mesh
          filename="package://omni_vehicle_urdf/meshes/base_link.STL" />
      </geometry>
    </collision>
  </link>
  <link
    name="right_motor_link">
    <inertial>
      <origin
        xyz="-3.1606E-07 0.030713 1.5981E-08"
        rpy="0 0 0" />
      <mass
        value="0.10956" />
      <inertia
        ixx="2.1439E-05"
        ixy="-1.6605E-19"
        ixz="1.4251E-21"
        iyy="3.7067E-05"
        iyz="8.1224E-21"
        izz="2.1439E-05" />
    </inertial>
    <visual>
      <origin
        xyz="0 0 0"
        rpy="0 0 0" />
      <geometry>
        <mesh
          filename="package://omni_vehicle_urdf/meshes/right_motor_link.STL" />
      </geometry>
      <material
        name="">
        <color
          rgba="0.64706 0.61961 0.58824 1" />
      </material>
    </visual>
    <collision>
      <origin
        xyz="0 0 0"
        rpy="0 0 0" />
      <geometry>
        <mesh
          filename="package://omni_vehicle_urdf/meshes/right_motor_link.STL" />
      </geometry>
    </collision>
  </link>
  <joint
    name="right_motor_joint"
    type="continuous">
    <origin
      xyz="0 -0.24424 -0.0485"
      rpy="0 0 0" />
    <parent
      link="base_link" />
    <child
      link="right_motor_link" />
    <axis
      xyz="0 -1 0" />
  </joint>
  <link
    name="right_tire_link">
    <inertial>
      <origin
        xyz="-3.0635E-07 0.014526 -2.455E-08"
        rpy="0 0 0" />
      <mass
        value="0.47617" />
      <inertia
        ixx="0.00023061"
        ixy="-2.5165E-18"
        ixz="5.4856E-10"
        iyy="0.00045211"
        iyz="-2.8198E-20"
        izz="0.00023061" />
    </inertial>
    <visual>
      <origin
        xyz="0 0 0"
        rpy="0 0 0" />
      <geometry>
        <mesh
          filename="package://omni_vehicle_urdf/meshes/right_tire_link.STL" />
      </geometry>
      <material
        name="">
        <color
          rgba="0.79216 0.81961 0.93333 1" />
      </material>
    </visual>
    <collision>
      <origin
        xyz="0 0 0"
        rpy="0 0 0" />
      <geometry>
        <mesh
          filename="package://omni_vehicle_urdf/meshes/right_tire_link.STL" />
      </geometry>
    </collision>
  </link>
  <joint
    name="right_tire_joint"
    type="fixed">
    <origin
      xyz="0 0 0"
      rpy="0 0 0" />
    <parent
      link="right_motor_link" />
    <child
      link="right_tire_link" />
    <axis
      xyz="0 0 0" />
  </joint>
  <link
    name="left_motor_link">
    <inertial>
      <origin
        xyz="2.0735E-07 -0.027713 6.0883E-08"
        rpy="0 0 0" />
      <mass
        value="0.10956" />
      <inertia
        ixx="2.1439E-05"
        ixy="9.5655E-21"
        ixz="-2.6292E-21"
        iyy="3.7067E-05"
        iyz="-8.1247E-21"
        izz="2.1439E-05" />
    </inertial>
    <visual>
      <origin
        xyz="0 0 0"
        rpy="0 0 0" />
      <geometry>
        <mesh
          filename="package://omni_vehicle_urdf/meshes/left_motor_link.STL" />
      </geometry>
      <material
        name="">
        <color
          rgba="0.64706 0.61961 0.58824 1" />
      </material>
    </visual>
    <collision>
      <origin
        xyz="0 0 0"
        rpy="0 0 0" />
      <geometry>
        <mesh
          filename="package://omni_vehicle_urdf/meshes/left_motor_link.STL" />
      </geometry>
    </collision>
  </link>
  <joint
    name="left_motor_joint"
    type="continuous">
    <origin
      xyz="0 0.23242 -0.0485"
      rpy="0 0 0" />
    <parent
      link="base_link" />
    <child
      link="left_motor_link" />
    <axis
      xyz="0 1 0" />
  </joint>
  <link
    name="left_tire_link">
    <inertial>
      <origin
        xyz="3.1046E-06 -0.011522 2.017E-05"
        rpy="0 0 0" />
      <mass
        value="0.47598" />
      <inertia
        ixx="0.00023061"
        ixy="7.7477E-15"
        ixz="4.7431E-16"
        iyy="0.00045211"
        iyz="4.7796E-15"
        izz="0.00023061" />
    </inertial>
    <visual>
      <origin
        xyz="0 0 0"
        rpy="0 0 0" />
      <geometry>
        <mesh
          filename="package://omni_vehicle_urdf/meshes/left_tire_link.STL" />
      </geometry>
      <material
        name="">
        <color
          rgba="0.79216 0.81961 0.93333 1" />
      </material>
    </visual>
    <collision>
      <origin
        xyz="0 0 0"
        rpy="0 0 0" />
      <geometry>
        <mesh
          filename="package://omni_vehicle_urdf/meshes/left_tire_link.STL" />
      </geometry>
    </collision>
  </link>
  <joint
    name="left_tire_joint"
    type="fixed">
    <origin
      xyz="0 0 0"
      rpy="0 0 0" />
    <parent
      link="left_motor_link" />
    <child
      link="left_tire_link" />
    <axis
      xyz="0 0 0" />
  </joint>
  <link
    name="front_motor_link">
    <inertial>
      <origin
        xyz="-2.9146E-07 0.030713 1.2327E-07"
        rpy="0 0 0" />
      <mass
        value="0.10956" />
      <inertia
        ixx="2.1439E-05"
        ixy="1.3495E-20"
        ixz="4.3044E-22"
        iyy="3.7067E-05"
        iyz="5.2736E-21"
        izz="2.1439E-05" />
    </inertial>
    <visual>
      <origin
        xyz="0 0 0"
        rpy="0 0 0" />
      <geometry>
        <mesh
          filename="package://omni_vehicle_urdf/meshes/front_motor_link.STL" />
      </geometry>
      <material
        name="">
        <color
          rgba="0.64706 0.61961 0.58824 1" />
      </material>
    </visual>
    <collision>
      <origin
        xyz="0 0 0"
        rpy="0 0 0" />
      <geometry>
        <mesh
          filename="package://omni_vehicle_urdf/meshes/front_motor_link.STL" />
      </geometry>
    </collision>
  </link>
  <joint
    name="front_motor_joint"
    type="continuous">
    <origin
      xyz="0.23517 0 -0.0485"
      rpy="0 0 1.5708" />
    <parent
      link="base_link" />
    <child
      link="front_motor_link" />
    <axis
      xyz="0 -1 0" />
  </joint>
  <link
    name="front_tire_link">
    <inertial>
      <origin
        xyz="-2.9623E-07 0.014526 8.1871E-08"
        rpy="0 0 0" />
      <mass
        value="0.47617" />
      <inertia
        ixx="0.00023061"
        ixy="-1.002E-20"
        ixz="-2.7495E-10"
        iyy="0.00045211"
        iyz="1.9408E-20"
        izz="0.00023061" />
    </inertial>
    <visual>
      <origin
        xyz="0 0 0"
        rpy="0 0 0" />
      <geometry>
        <mesh
          filename="package://omni_vehicle_urdf/meshes/front_tire_link.STL" />
      </geometry>
      <material
        name="">
        <color
          rgba="0.79216 0.81961 0.93333 1" />
      </material>
    </visual>
    <collision>
      <origin
        xyz="0 0 0"
        rpy="0 0 0" />
      <geometry>
        <mesh
          filename="package://omni_vehicle_urdf/meshes/front_tire_link.STL" />
      </geometry>
    </collision>
  </link>
  <joint
    name="front_tire_joint"
    type="fixed">
    <origin
      xyz="0 0 0"
      rpy="0 0 0" />
    <parent
      link="front_motor_link" />
    <child
      link="front_tire_link" />
    <axis
      xyz="0 0 0" />
  </joint>
  <link
    name="back_motor_link">
    <inertial>
      <origin
        xyz="1.6149E-07 -0.030713 2.7216E-07"
        rpy="0 0 0" />
      <mass
        value="0.10956" />
      <inertia
        ixx="2.1439E-05"
        ixy="1.5009E-20"
        ixz="2.2464E-21"
        iyy="3.7067E-05"
        iyz="3.3675E-21"
        izz="2.1439E-05" />
    </inertial>
    <visual>
      <origin
        xyz="0 0 0"
        rpy="0 0 0" />
      <geometry>
        <mesh
          filename="package://omni_vehicle_urdf/meshes/back_motor_link.STL" />
      </geometry>
      <material
        name="">
        <color
          rgba="0.64706 0.61961 0.58824 1" />
      </material>
    </visual>
    <collision>
      <origin
        xyz="0 0 0"
        rpy="0 0 0" />
      <geometry>
        <mesh
          filename="package://omni_vehicle_urdf/meshes/back_motor_link.STL" />
      </geometry>
    </collision>
  </link>
  <joint
    name="back_motor_joint"
    type="continuous">
    <origin
      xyz="-0.23496 0 -0.0485"
      rpy="0 0 1.5708" />
    <parent
      link="base_link" />
    <child
      link="back_motor_link" />
    <axis
      xyz="0 -1 0" />
  </joint>
  <link
    name="back_tire_link">
    <inertial>
      <origin
        xyz="1.8989E-07 -0.014526 2.4165E-07"
        rpy="0 0 0" />
      <mass
        value="0.47617" />
      <inertia
        ixx="0.00023061"
        ixy="2.5148E-20"
        ixz="1.2078E-09"
        iyy="0.00045211"
        iyz="9.3837E-21"
        izz="0.00023061" />
    </inertial>
    <visual>
      <origin
        xyz="0 0 0"
        rpy="0 0 0" />
      <geometry>
        <mesh
          filename="package://omni_vehicle_urdf/meshes/back_tire_link.STL" />
      </geometry>
      <material
        name="">
        <color
          rgba="0.79216 0.81961 0.93333 1" />
      </material>
    </visual>
    <collision>
      <origin
        xyz="0 0 0"
        rpy="0 0 0" />
      <geometry>
        <mesh
          filename="package://omni_vehicle_urdf/meshes/back_tire_link.STL" />
      </geometry>
    </collision>
  </link>
  <joint
    name="back_tire_joint"
    type="fixed">
    <origin
      xyz="0 0 0"
      rpy="0 0 0" />
    <parent
      link="back_motor_link" />
    <child
      link="back_tire_link" />
    <axis
      xyz="0 0 0" />
  </joint>
</robot>
